Workbook

Sheet RESUMEN
A1: INVENTARIO DE EMISIONES GEI — PABELLÓN DE ARTEAGA, AÑO BASE 2022 — v1.4 (recálculo)
A2: IPCC 2006 Nivel 2 (AFOLU, IPPU) · Protocolo GPC · GWP AR5 (CH₄ = 28; N₂O = 265). Todas las cifras son fórmulas.
A4: Sector | B4: Código IPCC | C4: CO₂ | D4: CH₄ (tCO₂e) | E4: N₂O (tCO₂e) | F4: HFC (tCO₂e) | G4: Total v1.4 (tCO₂e) | H4: % del total | I4: Total v1.0 (tCO₂e) | J4: Δ (tCO₂e)
A5: 1. Energía estacionaria | B5: 1.A | C5: =1_ENERGIA!$F$14 -> 77619.69 | D5: =0 -> 0 | E5: =0 -> 0 | F5: =0 -> 0 | G5: =SUM(C5:F5) -> 77619.69 | H5: =G5/$G$10 -> 0.37730643 | I5: 77619.69 | J5: =G5-I5 -> 0.00046685238
A6: 2. Autotransporte | B6: 1.A.3.b | C6: =2_AUTOTRANSPORTE!$D$18 -> 71877.067 | D6: =2_AUTOTRANSPORTE!$E$18 -> 236.08723 | E6: =2_AUTOTRANSPORTE!$F$18 -> 1527.0888 | F6: =0 -> 0 | G6: =SUM(C6:F6) -> 73640.243 | H6: =G6/$G$10 -> 0.35796248 | I6: 72113.15 | J6: =G6-I6 -> 1527.0932
A7: 3. AFOLU | B7: 3.A / 3.B / 3.C | C7: =3_AFOLU!$C$43 -> 14308.067 | D7: =3_AFOLU!$D$43 -> 16611.045 | E7: =3_AFOLU!$E$43 -> 7616.4524 | F7: =0 -> 0 | G7: =SUM(C7:F7) -> 38535.564 | H7: =G7/$G$10 -> 0.18731994 | I7: 42482.91 | J7: =G7-I7 -> -3947.346
A8: 4. Residuos | B8: 4.A / 4.D | C8: =0 -> 0 | D8: =4_RESIDUOS!$B$11+4_RESIDUOS!$B$25 -> 12079.121 | E8: =4_RESIDUOS!$B$31 -> 793.64623 | F8: =0 -> 0 | G8: =SUM(C8:F8) -> 12872.767 | H8: =G8/$G$10 -> 0.062574043 | I8: 1618.96 | J8: =G8-I8 -> 11253.807
A9: 5. IPPU | B9: 2.F / 2.H / 2.A | C9: =5_IPPU!$E$10 -> 520.8 | D9: =0 -> 0 | E9: =0 -> 0 | F9: =5_IPPU!$E$9 -> 2531.4973 | G9: =SUM(C9:F9) -> 3052.2973 | H9: =G9/$G$10 -> 0.014837104 | I9: 3645.09 | J9: =G9-I9 -> -592.79272
A10: TOTAL MUNICIPAL 2022 | B10: — | C10: =SUM(C5:C9) -> 164325.62 | D10: =SUM(D5:D9) -> 28926.253 | E10: =SUM(E5:E9) -> 9937.1874 | F10: =SUM(F5:F9) -> 2531.4973 | G10: =SUM(G5:G9) -> 205720.56 | H10: =SUM(H5:H9) -> 1 | I10: =SUM(I5:I9) -> 197479.8 | J10: =SUM(J5:J9) -> 8240.7622
A11: % por gas | C11: =C10/$G$10 -> 0.79878075 | D11: =D10/$G$10 -> 0.14060944 | E11: =E10/$G$10 -> 0.048304298 | F11: =F10/$G$10 -> 0.012305514
A13: Indicadores
A14: Indicador | B14: v1.4 | C14: v1.0 | D14: Unidad
A15: Emisiones totales | B15: =G10 -> 205720.56 | C15: =I10 -> 197479.8 | D15: tCO₂e/año
A16: Población | B16: =SUPUESTOS_FE!$B$5 -> 47646 | C16: =SUPUESTOS_FE!$B$5 -> 47646 | D16: hab.
A17: Emisiones per cápita | B17: =B15/B16 -> 4.317688 | C17: =C15/C16 -> 4.1447299 | D17: tCO₂e/hab/año
A18: Superficie (Decreto 185) | B18: =SUPUESTOS_FE!$B$8 -> 177.529 | C18: =SUPUESTOS_FE!$B$8 -> 177.529 | D18: km²
A19: Intensidad territorial | B19: =B15/B18 -> 1158.7998 | C19: =C15/C18 -> 1112.3805 | D19: tCO₂e/km²
A20: Participación de CO₂ | B20: =C10/G10 -> 0.79878075 | C20: 0.88 | D20: %
A21: Incertidumbre AFOLU (Método 1) | B21: =3_AFOLU!$G$43 -> 0.20562697 | C21: ±12–18 % | D21: ±%
A23: Medidas de mitigación cuantificadas del PAC 2026-2030 (tCO₂e/año al 2030)
A24: Medida | B24: Reducción | C24: Eje | D24: Nota
A25: E1-A Eficiencia energética | B25: 8500 | C25: Energía
A26: E1-B Fotovoltaica 5 MWp | B26: 4313 | C26: Energía | D26: 5 MWp × 1,900 kWh/kWp × 0.454
A27: E1-C Gas LP → solar/biogás | B27: 2500 | C27: Energía
A28: T2-A Movilidad no motorizada | B28: 2100 | C28: Transporte
A29: T2-B Flota y verificación | B29: 5800 | C29: Transporte
A30: T2-C Gestión de la demanda | B30: 1500 | C30: Transporte
A31: M3-A Biodigestores porcinos | B31: =ROUND(3B_ESTIERCOL!$C$19,-1) -> 6110 | C31: AFOLU | D31: 80 % de la laguna, −5 % fugas
A32: M3-B Estiércol bovino/avícola | B32: 400 | C32: AFOLU
A33: M3-C Fertilizantes | B33: 1900 | C33: AFOLU
A34: M3-D Cambio de uso de suelo −50 % | B34: =ROUND(0.5*3_AFOLU!$F$32,-1) -> 7150 | C34: AFOLU | D34: 50 % del promedio anual
A35: R4-A Separación y compostaje | B35: 490 | C35: Residuos | D35: Estimación conservadora
A36: R4-C Saneamiento | B36: 75 | C36: Residuos
A37: I5-A Sustitución de HFC | B37: 800 | C37: IPPU
A38: I5-C Proceso avícola | B38: 80 | C38: IPPU
A39: Total medidas cuantificadas (no condicionadas) | B39: =SUM(B25:B38) -> 41718
A40: R4-B Biogás del relleno (condicionada, Alcance 3) | B40: =ROUND(0.5*4A_RSU_FOD!$AN$61,-1) -> 3400 | D40: 50 % de captura sobre la emisión 2030 de los residuos depositados en el CARS La Loma (desde 2022); no computa en la meta no condicionada
A42: Metas del PAC 2030
A43: Concepto | B43: Valor | C43: Unidad
A44: Meta no condicionada | B44: =CRITERIOS!$B$19 -> 0.2 | C44: %
...

Sheet CRITERIOS
A1: CRITERIOS DE CÁLCULO — v1.4 (celdas amarillas = palancas que puedes cambiar)
A2: Cambia solo las celdas amarillas; todo el libro se recalcula. Los valores actuales son los recomendados tras la auditoría del 17-oct-2026.
A4: Criterio | B4: Valor | C4: Unidad | D4: Justificación / fuente
A5: UTCUTS — años del periodo de conversión (anualización) | B5: 5 | C5: años | D5: Series VI/VII INEGI no fechan la conversión dentro del periodo 2017–2022; se reparte el acumulado en partes iguales (hallazgo C1).
A6: UTCUTS — carbono en biomasa del cultivo que reemplaza la vegetación | B6: 5 | C6: tC/ha | D6: IPCC 2006 Vol.4 Cap.5, Tabla 5.9: cultivos anuales 5 tC/ha. Pon 0 para no descontar (hallazgo C1).
A7: Aguas residuales — MCF planta de lodos activados (cabecera) | B7: 0.03 | C7: fracción | D7: Refinamiento IPCC 2019, Vol.5 Cap.6, Tabla 6.3 (planta aerobia centralizada). VERIFICAR en la tabla y con datos de operación de INAGUA (administra las PTAR del estado). 0 = IPCC 2006 bien operada; 0.3 = sobrecargada (hallazgo C2).
A8: Aguas residuales — MCF viviendas sin drenaje (fosa séptica) | B8: 0.5 | C8: fracción | D8: IPCC 2006 Vol.5 Tabla 6.3, sistema séptico.
A9: Aguas residuales — Bo capacidad máx. de CH₄ | B9: 0.6 | C9: kg CH₄/kg DBO | D9: IPCC 2006 Vol.5 Tabla 6.2.
A10: Cobertura de drenaje (fracción de población conectada) | B10: 0.99 | C10: fracción | D10: INEGI 2020 / PDM 2024: 99.0 % de viviendas (hallazgo m3).
A11: RSU — fracción dispuesta en relleno sanitario | B11: 1 | C11: fracción | D11: PDM 2024: 100 % recolectado, sin tiraderos a cielo abierto (hallazgo m3).
A12: RSU — factor de oxidación | B12: 0.1 | C12: fracción | D12: IPCC 2006 Vol.5 Tabla 3.2, relleno gestionado con cobertura. Un solo valor en todo el libro (hallazgo m3).
A13: Incluir cal en construcción (2.A.2) en el total | B13: NO | C13: SI/NO | D13: El uso de cal no emite CO₂; solo la producción (calcinación). Cambia a SI solo si existe calera en el municipio (hallazgo M3).
A14: Incluir COV textiles (2.H.3) en el total | B14: NO | C14: SI/NO | D14: Los COV no son GEI del IPCC; se reportan como partida informativa (hallazgo M4).
A15: RSU — primer año de disposición en relleno (modelo FOD) | B15: 2001 | C15: año | D15: IMBIO: desde 2001 los RSU se envían, vía estaciones de transferencia, al relleno sanitario de San Nicolás (municipio de Aguascalientes).
A16: RSU — año de inicio en el CARS La Loma (Tepezalá) | B16: 2022 | C16: año | D16: IMBIO: desde 2022 los RSU se disponen en el CARS La Loma, Tepezalá, operado por Promotora Ambiental (PASA) (Informe PEPGIR 2025). Separa la emisión heredada (San Nicolás) de la del relleno actual.
A17: Temperatura media anual del municipio | B17: 18.7 | C17: °C | D17: Estación 1102 Pabellón de Arteaga (DGE), Normal Climatológica 1991-2020 SMN/CONAGUA (Atlas de Riesgos v2.0, Tabla 4). Define los MCF de estiércol por temperatura (IPCC 2006, Tabla 10.17).
A18: Meta de reducción del PAC al 2030 (condicionada) | B18: 0.3 | C18: fracción | D18: PAC 2026-2030 §3.2: meta condicionada a financiamiento externo.
A19: Meta de reducción del PAC al 2030 (no condicionada) | B19: 0.2 | C19: fracción | D19: PAC 2026-2030 §3.2: meta con recursos y facultades municipales.
A21: Leyenda: texto azul = dato de entrada · texto negro = fórmula · texto verde = vínculo a otra hoja · fondo amarillo = criterio ajustable · fondo salmón = valor heredado de v1.0 sin cálculo reproducible (revisar).

Sheet SUPUESTOS_FE
A1: DATOS GENERALES, GWP Y FACTORES DE EMISIÓN
A2: Fuente de cada valor en la columna D. Texto azul = dato de entrada.
A4: Parámetro | B4: Valor | C4: Unidad | D4: Fuente
A5: Población municipal 2022 (Censo 2020) | B5: 47646 | C5: hab. | D5: INEGI, Censo 2020
A6: Población estatal (Censo 2020) | B6: 1425607 | C6: hab. | D6: INEGI, Censo 2020
A7: Factor de prorrateo poblacional | B7: =B5/B6 -> 0.033421553 | C7: fracción | D7: Cálculo
A8: Superficie municipal oficial | B8: 177.529 | C8: km² | D8: Decreto 185, H. Congreso del Estado (2001) (hallazgo m1)
A9: GWP CH₄ | B9: 28 | C9: — | D9: IPCC AR5 Tabla 8.7
A10: GWP N₂O | B10: 265 | C10: — | D10: IPCC AR5 Tabla 8.7
A11: GWP HFC-134a | B11: 1430 | C11: — | D11: IPCC AR5 Tabla 8.7
A12: GWP HFC-410A | B12: 2088 | C12: — | D12: IPCC AR5 Tabla 8.7
A13: Conversión N₂O-N → N₂O (44/28) | B13: =44/28 -> 1.5714286 | C13: — | D13: Estequiometría
A14: Conversión C → CO₂ (44/12) | B14: =44/12 -> 3.6666667 | C14: — | D14: Estequiometría
A15: FE electricidad SIN 2022 | B15: 0.454 | C15: kgCO₂/kWh | D15: SENER/CFE, FE del SEN 2022
A16: FE gas LP | B16: 1.617 | C16: kgCO₂/L | D16: INECC / IPCC 2006 Vol.2 T.1.4
A17: FE gasolina CO₂ | B17: 2.24 | C17: kgCO₂/L | D17: IPCC 2006 Vol.2 T.2.2
A18: FE diésel CO₂ | B18: 2.68 | C18: kgCO₂/L | D18: IPCC 2006 Vol.2 T.2.2
A19: FE gasolina CH₄ | B19: 0.00038 | C19: kgCH₄/L | D19: IPCC 2006 Vol.2 T.3.2.2 (valor de v1.0)
A20: FE gasolina N₂O | B20: 0.00024 | C20: kgN₂O/L | D20: IPCC 2006 Vol.2 T.3.2.2 (valor de v1.0)
A21: FE diésel CH₄ | B21: 0.00014 | C21: kgCH₄/L | D21: IPCC 2006 Vol.2 T.3.2.2 (valor de v1.0)
A22: FE diésel N₂O | B22: 0.000125 | C22: kgN₂O/L | D22: IPCC 2006 Vol.2 T.3.2.2 (valor de v1.0)
A23: EF1 N₂O directo suelos (semiárido) | B23: 0.0096 | C23: kgN₂O-N/kgN | D23: INECC 2022
A24: FracGASF volatilización de fertilizante sintético | B24: 0.1 | C24: fracción | D24: IPCC 2019 Ec. 11.9
A25: FracLEACH lixiviación | B25: 0.07 | C25: fracción | D25: IPCC 2019 T.11.3 (semiárido, valor de v1.0)
A26: EF4 N₂O de N volatilizado | B26: 0.01 | C26: kgN₂O-N/kgN | D26: IPCC 2006/2019
... A32: EF N₂O efluentes | B32: 0.005 | C32: kgN₂O-N/kgN | D32: IPCC 2006 Vol.5 T.6.11

Sheet 1_ENERGIA
A1: SECTOR 1 — ENERGÍA ESTACIONARIA [1.A]
A2: E (tCO₂) = MWh × FE (kgCO₂/kWh) | Gas LP: L × FE (kgCO₂/L) / 1000
A4: Subsector | B4: Consumo (MWh/año) | C4: FE (kgCO₂/kWh) | D4: E CO₂ (t/año) | E4: Calidad | F4: Fuente
A5: Residencial | B5: 77040 | C5: =SUPUESTOS_FE!$B$15 -> 0.454 | D5: =B5*C5 -> 34976.16 | E5: Ex | F5: Prorrateo 3.342 % del consumo estatal (hallazgo m4)
A6: Comercial y servicios | B6: 38520 | C6: =SUPUESTOS_FE!$B$15 -> 0.454 | D6: =B6*C6 -> 17488.08 | E6: Ex | F6: Prorrateo 3.342 % del consumo estatal (hallazgo m4)
A7: Industrial | B7: 21440 | C7: =SUPUESTOS_FE!$B$15 -> 0.454 | D7: =B7*C7 -> 9733.76 | E7: Ex | F7: Prorrateo 3.342 % del consumo estatal (hallazgo m4)
A8: Alumbrado público | B8: 3200 | C8: =SUPUESTOS_FE!$B$15 -> 0.454 | D8: =B8*C8 -> 1452.8 | E8: D | F8: H. Ayuntamiento 2022
A9: Subtotal electricidad | B9: =SUM(B5:B8) -> 140200 | D9: =SUM(D5:D8) -> 63650.8
A11: Gas LP residencial | B11: Consumo estatal (L/año) | C11: Factor prorrateo | D11: Consumo municipal (L/año) | E11: FE (kgCO₂/L) | F11: E CO₂ (t/año)
A12: Gas LP en hogares | B12: 258479000 | C12: =SUPUESTOS_FE!$B$7 -> 0.033421553 | D12: =B12*C12 -> 8638769.6 | E12: =SUPUESTOS_FE!$B$16 -> 1.617 | F12: =D12*E12/1000 -> 13968.89
A14: TOTAL SECTOR 1 (tCO₂/año) | F14: =$D$9+$F$12 -> 77619.69
A16: Fuente gas LP: ENIGH 2022 / SIE-SENER Ags. El factor de prorrateo es la fórmula Pob. mun./Pob. est., lo que unifica el consumo con el del Inventario (8,638,770 L) (hallazgo N7).

Sheet 2_AUTOTRANSPORTE
A1: SECTOR 2 — AUTOTRANSPORTE [1.A.3.b]
A2: Consumo (L) = N_veh × km × L/100km / 100 | E_gas = L × FE × GWP / 1000 (t) | Ajuste por tráfico foráneo GPC
A4: Parámetro | B4: Valor | C4: Unidad | D4: Calidad | E4: Fuente
A5: Padrón vehicular 2022 | B5: 16200 | C5: vehículos | D5: Ex | E5: SEIEG 2024 extrapolado a 2022 (hallazgo m4)
A6: Fracción gasolina | B6: 0.85 | C6: fracción | D6: Ex | E6: INEGYCEI 2018 mix nacional
A7: km/año por vehículo de gasolina | B7: 15000 | C7: km | D7: Ex | E7: INEGI Módulo Movilidad 2022
A8: km/año por vehículo de diésel/carga | B8: 40000 | C8: km | D8: Ex | E8: INEGI / IPCC T.3.2.2
A9: Rendimiento gasolina | B9: 10.5 | C9: L/100 km | D9: Ex | E9: IPCC 2006 T.3.2.2
A10: Rendimiento diésel | B10: 15 | C10: L/100 km | D10: Ex | E10: IPCC 2006 T.3.2.2
A11: Ajuste por tráfico extramunicipal | B11: 0.18 | C11: fracción | D11: E | E11: Protocolo GPC, origen-destino
A13: Combustible | B13: Vehículos | C13: Consumo (L/año) | D13: CO₂ (tCO₂) | E13: CH₄ (tCO₂e) | F13: N₂O (tCO₂e) | G13: Total (tCO₂e)
A14: Gasolina | B14: =B5*B6 -> 13770 | C14: =B14*B7*B9/100 -> 21687750 | D14: =C14*SUPUESTOS_FE!$B$17/1000 -> 48580.56 | E14: =C14*SUPUESTOS_FE!$B$19/1000*SUPUESTOS_FE!$B$9 -> 230.75766 | F14: =C14*SUPUESTOS_FE!$B$20/1000*SUPUESTOS_FE!$B$10 -> 1379.3409 | G14: =SUM(D14:F14) -> 50190.659
A15: Diésel / carga | B15: =B5*(1-B6) -> 2430 | C15: =B15*B8*B10/100 -> 14580000 | D15: =C15*SUPUESTOS_FE!$B$18/1000 -> 39074.4 | E15: =C15*SUPUESTOS_FE!$B$21/1000*SUPUESTOS_FE!$B$9 -> 57.1536 | F15: =C15*SUPUESTOS_FE!$B$22/1000*SUPUESTOS_FE!$B$10 -> 482.9625 | G15: =SUM(D15:F15) -> 39614.516
A16: Total bruto | D16: =SUM(D14:D15) -> 87654.96 | E16: =SUM(E14:E15) -> 287.91126 | F16: =SUM(F14:F15) -> 1862.3034 | G16: =SUM(G14:G15) -> 89805.175
A17: (−) Ajuste tráfico extramunicipal | D17: =-D16*$B$11 -> -15777.893 | E17: =-E16*$B$11 -> -51.824027 | F17: =-F16*$B$11 -> -335.21461 | G17: =-G16*$B$11 -> -16164.931
A18: TOTAL SECTOR 2 (tCO₂e/año) | D18: =D16+D17 -> 71877.067 | E18: =E16+E17 -> 236.08723 | F18: =F16+F17 -> 1527.0888 | G18: =G16+G17 -> 73640.243
A20: v1.1: unidades corregidas (antes 48.58 «tCO₂» = 48,580.6), CH₄ separado del CO₂ y N₂O móvil añadido con los FE de SUPUESTOS_FE (hallazgos M6 y N5).

Sheet 3B_ESTIERCOL
A1: 3.A.2 GESTIÓN DE ESTIÉRCOL — NIVEL 2 (IPCC 2006 Vol.4 Cap.10 / Refinamiento 2019)
A2: CH₄ = Cab × AWMS × VS × 365 × Bo × 0.67 × MCF / 1000 (t) | N₂O dir = Cab × AWMS × Nex × EF3 × 44/28 | N₂O ind = Cab × AWMS × Nex × FracGasMS × EF4 × 44/28
A4: Especie / sistema | B4: Cabezas | C4: AWMS (fracción) | D4: VS (kg/cab/día) | E4: Bo (m³CH₄/kg VS) | F4: MCF (fracción) | G4: CH₄ (t/año) | H4: Nex (kgN/cab/año) | I4: EF3 (kgN₂O-N/kgN) | J4: FracGasMS | K4: N₂O dir. (tCO₂e) | L4: N₂O ind. (tCO₂e) | M4: Fuente / nota | O4: T (°C) | P4: MCF laguna
A5: Bovino — corral seco | B5: 4820 | C5: 0.95 | D5: 5.94 | E5: 0.17 | F5: =IF(CRITERIOS!$B$17<15,0.01,IF(CRITERIOS!$B$17<=25,0.015,0.02)) -> 0.015 | G5: =B5*C5*D5*365*E5*0.67*F5/1000 -> 16.961527 | H5: 51 | I5: 0.02 | J5: 0.3 | K5: =B5*C5*H5*I5*SUPUESTOS_FE!$B$13/1000*SUPUESTOS_FE!$B$10 -> 1944.963 | L5: =B5*C5*H5*J5*SUPUESTOS_FE!$B$26*SUPUESTOS_FE!$B$13/1000*SUPUESTOS_FE!$B$10 -> 291.74444 | M5: MCF por temperatura (IPCC 2006 T10.17, corral seco templado). EF3 0.02 de corral seco (IPCC 2006 T10.21): el estiércol se acumula largo tiempo antes de retirarse (IMBIO). FracGasMS: IPCC 2006 T10.22. | O5: 10 | P5: 0.66
A6: Bovino — pastoreo estacional | B6: 4820 | C6: 0.05 | D6: 5.94 | E6: 0.17 | F6: 0.0047 | G6: =B6*C6*D6*365*E6*0.67*F6/1000 -> 0.2797164 | H6: 51 | I6: 0 | J6: 0 | K6: =B6*C6*H6*I6*SUPUESTOS_FE!$B$13/1000*SUPUESTOS_FE!$B$10 -> 0 | L6: =B6*C6*H6*J6*SUPUESTOS_FE!$B$26*SUPUESTOS_FE!$B$13/1000*SUPUESTOS_FE!$B$10 -> 0 | M6: N depositado en pastoreo corresponde a 3.C.4 (PRP); no se estima aquí. | O6: 11 | P6: 0.68
A7: Porcino — laguna anaerobia | B7: 12450 | C7: 0.8 | D7: 0.34 | E7: 0.45 | F7: =INDEX($P$5:$P$23,MATCH(MAX(10,MIN(28,ROUND(CRITERIOS!$B$17,0))),$O$5:$O$23,0)) -> 0.77 | G7: =B7*C7*D7*365*E7*0.67*F7/1000 -> 286.95194 | H7: 12.6 | I7: 0.005 | J7: 0.4 | K7: =B7*C7*H7*I7*SUPUESTOS_FE!$B$13/1000*SUPUESTOS_FE!$B$10 -> 261.3006 | L7: =B7*C7*H7*J7*SUPUESTOS_FE!$B$26*SUPUESTOS_FE!$B$13/1000*SUPUESTOS_FE!$B$10 -> 209.04048 | M7: MCF de laguna según temperatura media anual (IPCC 2006 T10.17, tabla a la derecha). FracGasMS IPCC 2006 T10.22. | O7: 12 | P7: 0.7
A8: Porcino — sólido cubierto | B8: 12450 | C8: 0.2 | D8: 0.34 | E8: 0.45 | F8: =IF(CRITERIOS!$B$17<15,0.02,IF(CRITERIOS!$B$17<=25,0.04,0.05)) -> 0.04 | G8: =B8*C8*D8*365*E8*0.67*F8/1000 -> 3.7266485 | H8: 12.6 | I8: 0.005 | J8: 0.5 | K8: =B8*C8*H8*I8*SUPUESTOS_FE!$B$13/1000*SUPUESTOS_FE!$B$10 -> 65.32515 | L8: =B8*C8*H8*J8*SUPUESTOS_FE!$B$26*SUPUESTOS_FE!$B$13/1000*SUPUESTOS_FE!$B$10 -> 65.32515 | M8: MCF de almacenamiento sólido por clima (IPCC 2006 T10.17: frío 2 %, templado 4 %, cálido 5 %). EF3 y FracGasMS: IPCC 2006 T10.21/T10.22. | O8: 13 | P8: 0.71
A9: Avícola — cama de pollos | B9: 285000 | C9: 1 | D9: 0.014 | E9: 0.36 | F9: 0.015 | G9: =B9*C9*D9*365*E9*0.67*F9/1000 -> 5.2690743 | H9: 0.34 | I9: 0.001 | J9: 0.4 | K9: =B9*C9*H9*I9*SUPUESTOS_FE!$B$13/1000*SUPUESTOS_FE!$B$10 -> 40.351929 | L9: =B9*C9*H9*J9*SUPUESTOS_FE!$B$26*SUPUESTOS_FE!$B$13/1000*SUPUESTOS_FE!$B$10 -> 161.40771 | M9: VS, Bo, MCF, Nex: SUPUESTOS v1.0. EF3 y FracGasMS: IPCC 2006 T10.21/T10.22 (aves con cama). | O9: 14 | P9: 0.73
O10: 15 | P10: 0.74
A11: Resumen por especie (tCO₂e/año) | O11: 16 | P11: 0.75
A12: Especie | B12: Cabezas | C12: CH₄ (tCO₂e) | D12: N₂O directo | E12: N₂O indirecto | F12: Total | O12: 17 | P12: 0.76
A13: Bovino | B13: =B5 -> 4820 | C13: =(G5+G6)*SUPUESTOS_FE!$B$9 -> 482.7548 | D13: =K5+K6 -> 1944.963 | E13: =L5+L6 -> 291.74444 | F13: =SUM(C13:E13) -> 2719.4622 | O13: 18 | P13: 0.77
A14: Porcino | B14: =B7 -> 12450 | C14: =(G7+G8)*SUPUESTOS_FE!$B$9 -> 8139.0004 | D14: =K7+K8 -> 326.62575 | E14: =L7+L8 -> 274.36563 | F14: =SUM(C14:E14) -> 8739.9918 | O14: 19 | P14: 0.77
A15: Avícola | B15: =B9 -> 285000 | C15: =(G9)*SUPUESTOS_FE!$B$9 -> 147.53408 | D15: =K9 -> 40.351929 | E15: =L9 -> 161.40771 | F15: =SUM(C15:E15) -> 349.29372 | O15: 20 | P15: 0.78
O16: 21 | P16: 0.78
A17: CH₄ de la laguna porcina (base de la medida M3-A) | C17: =G7*SUPUESTOS_FE!$B$9 -> 8034.6543 | O17: 22 | P17: 0.78
A18: Techo técnico M3-A: 80 % de granjas a biodigestor | C18: =0.8*C17 -> 6427.7234 | O18: 23 | P18: 0.79
A19: Potencial M3-A descontando 5 % de fugas | C19: =C18*0.95 -> 6106.3372 | O19: 24 | P19: 0.79
O20: 25 | P20: 0.79
A21: Los MCF de corral seco, laguna y almacenamiento sólido se calculan con la temperatura media anual de CRITERIOS (IPCC 2006, Tabla 10.17). | O21: 26 | P21: 0.79
O22: 27 | P22: 0.8
O23: 28 | P23: 0.8
O25: IPCC 2006 Vol.4 Tabla 10.17 (laguna anaerobia sin cubierta); verificar contra la tabla.

Sheet 3_AFOLU
A1: SECTOR 3 — AFOLU NIVEL 2 [3.A / 3.B / 3.C]
A3: A) Fermentación entérica [3.A.1] — E = cabezas × FE / 1000 × GWP
A4: Categoría | B4: Cabezas 2022 | C4: FE (kgCH₄/cab/año) | D4: CH₄ (t/año) | E4: E (tCO₂e) | H4: Fuente FE
A5: Vacas lecheras (Holstein × Suizo Eur.) | B5: 1687 | C5: 53.7 | D5: =B5*C5/1000 -> 90.5919 | E5: =D5*SUPUESTOS_FE!$B$9 -> 2536.5732 | H5: INIFAP 2023
A6: Bovinos carne — machos adultos | B6: 2651 | C6: 55.8 | D6: =B6*C6/1000 -> 147.9258 | E6: =D6*SUPUESTOS_FE!$B$9 -> 4141.9224 | H6: INIFAP 2023
A7: Vaquillas / becerros (<2 años) | B7: 482 | C7: 35 | D7: =B7*C7/1000 -> 16.87 | E7: =D7*SUPUESTOS_FE!$B$9 -> 472.36 | H7: IPCC 2019 T.10.10
A8: Porcino (peso vivo prom. 80 kg) | B8: 12450 | C8: 1.5 | D8: =B8*C8/1000 -> 18.675 | E8: =D8*SUPUESTOS_FE!$B$9 -> 522.9 | H8: IPCC 2019 T.10.10
A9: Ovino / caprino | B9: 1200 | C9: 5 | D9: =B9*C9/1000 -> 6 | E9: =D9*SUPUESTOS_FE!$B$9 -> 168 | H9: IPCC 2006 T.10.11
A10: Total fermentación entérica | D10: =SUM(D5:D9) -> 280.0627 | E10: =SUM(E5:E9) -> 7841.7556
A12: B) Gestión de estiércol [3.A.2] — cálculo completo en la hoja 3B_ESTIERCOL
A13: Especie | B13: Cabezas | C13: CH₄ (tCO₂e) | D13: N₂O directo (tCO₂e) | E13: N₂O indirecto (tCO₂e) | F13: Total (tCO₂e) | H13: Nota
A14: Bovino — corral seco 95 % / pastoreo 5 % | B14: =3B_ESTIERCOL!$B$13 -> 4820 | C14: =3B_ESTIERCOL!$C$13 -> 482.7548 | D14: =3B_ESTIERCOL!$D$13 -> 1944.963 | E14: =3B_ESTIERCOL!$E$13 -> 291.74444 | F14: =SUM(C14:E14) -> 2719.4622 | H14: v1.2: reconstruido con VS, Bo, MCF, Nex, EF3 y FracGasMS documentados en 3B_ESTIERCOL (hallazgo N8).
A15: Porcino — laguna anaerobia 80 % / sólido 20 % | B15: =3B_ESTIERCOL!$B$14 -> 12450 | C15: =3B_ESTIERCOL!$C$14 -> 8139.0004 | D15: =3B_ESTIERCOL!$D$14 -> 326.62575 | E15: =3B_ESTIERCOL!$E$14 -> 274.36563 | F15: =SUM(C15:E15) -> 8739.9918
A16: Avícola — cama de pollos | B16: =3B_ESTIERCOL!$B$15 -> 285000 | C16: =3B_ESTIERCOL!$C$15 -> 147.53408 | D16: =3B_ESTIERCOL!$D$15 -> 40.351929 | E16: =3B_ESTIERCOL!$E$15 -> 161.40771 | F16: =SUM(C16:E16) -> 349.29372
A17: Total gestión de estiércol | C17: =SUM(C14:C16) -> 8769.2893 | D17: =SUM(D14:D16) -> 2311.9406 | E17: =SUM(E14:E16) -> 727.51779 | F17: =SUM(F14:F16) -> 11808.748
A19: C) Suelos agrícolas — N₂O [3.C.4 / 3.C.5] — E = N × EF × 44/28 × GWP
A20: Fuente | B20: N base (tN/año) | C20: Fracción | D20: EF (kgN₂O-N/kgN) | E20: N₂O (t/año) | F20: E (tCO₂e) | H20: Nota
A21: FSN directo — fertilizantes sintéticos | B21: 773.92 | C21: 1 | D21: =SUPUESTOS_FE!$B$23 -> 0.0096 | E21: =B21*C21*D21*SUPUESTOS_FE!$B$13 -> 11.675136 | F21: =E21*SUPUESTOS_FE!$B$10 -> 3093.911 | H21: SIAP 2022 / INIFAP 2023
A22: FCR directo — residuos de cultivo | B22: 211.34 | C22: 1 | D22: =SUPUESTOS_FE!$B$23 -> 0.0096 | E22: =B22*C22*D22*SUPUESTOS_FE!$B$13 -> 3.1882149 | F22: =E22*SUPUESTOS_FE!$B$10 -> 844.87694 | H22: v1.0 mostraba 856.93; el cálculo da 844.88 (hallazgo m5)
A23: Indirecto — volatilización (sobre FSN) | B23: =B21 -> 773.92 | C23: =SUPUESTOS_FE!$B$24 -> 0.1 | D23: =SUPUESTOS_FE!$B$26 -> 0.01 | E23: =B23*C23*D23*SUPUESTOS_FE!$B$13 -> 1.21616 | F23: =E23*SUPUESTOS_FE!$B$10 -> 322.2824 | H23: IPCC Ec. 11.9: solo FSN volatiliza (no FCR). v1.0: base 98.53 y resultado 10× menor (hallazgos C3, m5)
A24: Indirecto — lixiviación (FSN + FCR) | B24: =B21+B22 -> 985.26 | C24: =SUPUESTOS_FE!$B$25 -> 0.07 | D24: =SUPUESTOS_FE!$B$27 -> 0.011 | E24: =B24*C24*D24*SUPUESTOS_FE!$B$13 -> 1.1921646 | F24: =E24*SUPUESTOS_FE!$B$10 -> 315.92362 | H24: v1.0: 31.59, 10× menor (hallazgo C3)
A25: Total suelos agrícolas | F25: =SUM(F21:F24) -> 4576.994
A27: D) Cambio de uso de suelo [3.B] — E = ha × (C veg − C cultivo) × 44/12 ÷ años del periodo
A28: Vegetación convertida → agrícola | B28: Superficie (ha) | C28: C vegetación (tC/ha) | D28: C cultivo (tC/ha) | E28: CO₂ acumulado 2017–22 (t) | F28: CO₂ anual (t/año) | H28: Fuente
A29: Matorral crasicaule | B29: 390 | C29: 23.5 | D29: =CRITERIOS!$B$6 -> 5 | E29: =B29*(C29-D29)*SUPUESTOS_FE!$B$14 -> 26455 | F29: =E29/CRITERIOS!$B$5 -> 5291 | H29: INEGI VI/VII + literatura regional
A30: Bosque de encino degradado | B30: 130 | C30: 75.4 | D30: =CRITERIOS!$B$6 -> 5 | E30: =B30*(C30-D30)*SUPUESTOS_FE!$B$14 -> 33557.333 | F30: =E30/CRITERIOS!$B$5 -> 6711.4667 | H30: Acta Botánica Mexicana 2020
A31: Selva baja caducifolia | B31: 60 | C31: 57.4 | D31: =CRITERIOS!$B$6 -> 5 | E31: =B31*(C31-D31)*SUPUESTOS_FE!$B$14 -> 11528 | F31: =E31/CRITERIOS!$B$5 -> 2305.6 | H31: Sociedad Botánica de México 2016
A32: Total UTCUTS | B32: =SUM(B29:B31) -> 580 | E32: =SUM(E29:E31) -> 71540.333 | F32: =SUM(F29:F31) -> 14308.067
A33: v1.0 reportaba 22,940 tCO₂, cifra que no se reproduce con estos datos (el acumulado sin descontar cultivo es 82,175.60). Sin carbono de suelo. Verificar con ≥30 parcelas en el ciclo 2028 (hallazgo C1).
A35: E) Resumen AFOLU por subcategoría y gas
A36: Subcategoría | B36: Código | C36: CO₂ | D36: CH₄ | E36: N₂O | F36: Total (tCO₂e) | G36: Incert. (±%)
A37: Fermentación entérica | B37: 3.A.1 | C37: 0 | D37: =$E$10 -> 7841.7556 | E37: 0 | F37: =SUM(C37:E37) -> 7841.7556 | G37: 0.18
A38: Gestión de estiércol — CH₄ | B38: 3.A.2 | C38: 0 | D38: =$C$17 -> 8769.2893 | E38: 0 | F38: =SUM(C38:E38) -> 8769.2893 | G38: 0.27
A39: Gestión de estiércol — N₂O | B39: 3.A.2 | C39: 0 | D39: 0 | E39: =$D$17+$E$17 -> 3039.4584 | F39: =SUM(C39:E39) -> 3039.4584 | G39: 0.38
A40: Suelos agrícolas — N₂O directo | B40: 3.C.4 | C40: 0 | D40: 0 | E40: =F21+F22 -> 3938.788 | F40: =SUM(C40:E40) -> 3938.788 | G40: 0.41
A41: Suelos agrícolas — N₂O indirecto | B41: 3.C.5 | C41: 0 | D41: 0 | E41: =F23+F24 -> 638.20602 | F41: =SUM(C41:E41) -> 638.20602 | G41: 0.41
A42: UTCUTS | B42: 3.B | C42: =$F$32 -> 14308.067 | D42: 0 | E42: 0 | F42: =SUM(C42:E42) -> 14308.067 | G42: 0.5
A43: TOTAL AFOLU | C43: =SUM(C37:C42) -> 14308.067 | D43: =SUM(D37:D42) -> 16611.045 | E43: =SUM(E37:E42) -> 7616.4524 | F43: =SUM(F37:F42) -> 38535.564 | G43: =SQRT(SUMPRODUCT((F37:F42*G37:G42)^2))/F43 -> 0.20562697
A44: Incertidumbre del sector por Método 1 IPCC (suma cuadrática ponderada por emisiones), con las incertidumbres por subcategoría de la Tabla 9.1 del Inventario (hallazgo C6).

Sheet 4A_RSU_FOD
A1: 4.A RSU — MODELO DE PRIMER ORDEN (FOD), IPCC 2006 Vol.5 Cap.3
A2: DDOCm = W × fracción × DOC × DOCf × MCF | DDOCma(T) = DDOCm(T) + DDOCma(T−1)·e^(−k) | descompuesto(T) = DDOCma(T−1)·(1 − e^(−k)) | CH₄ = descompuesto × F × 16/12 × (1 − OX)
A4: Parámetro | B4: Alimentos | C4: Jardinería | D4: Papel y cartón | E4: Madera | F4: Textiles | G4: Pañales | H4: Fuente
A5: Fracción en RSU (húmedo) | B5: 0.3666 | C5: 0.147 | D5: 0.1559 | E5: 0.0028 | F5: 0.0102 | G5: 0.0942 | H5: Caracterización de Pabellón de Arteaga 2025 (Informe final PEPGIR Aguascalientes, Tabla 1.38): alimentos 36.66; jardinería 13.90 + fibra dura vegetal 0.80; cartón 4.78 + papel 1.53 + papel sanitario 8.49 + cartón encerado 0.08 + Tetrapak 0.71; madera 0.28; trapo 1.02; pañal 9.42.
A6: DOC (fracción, base húmeda) | B6: 0.15 | C6: 0.2 | D6: 0.4 | E6: 0.43 | F6: 0.24 | G6: 0.24 | H6: IPCC 2006 Vol.5 T2.4
A7: k (1/año) | B7: 0.06 | C7: 0.05 | D7: 0.04 | E7: 0.02 | F7: 0.04 | G7: 0.04 | H7: IPCC 2006 Vol.5 T3.3, clima templado seco (TMA ≤20 °C; P/ETP <1). Pañales: k de degradación lenta (supuesto).
A9: DOCf | B9: 0.5 | C9: IPCC 2006 Vol.5 §3.2.3
A10: MCF relleno gestionado anaerobio | B10: 1 | C10: IPCC 2006 Vol.5 T3.1
A11: F (fracción de CH₄ en biogás) | B11: 0.5 | C11: IPCC 2006 Vol.5 §3.2.3
A12: OX (oxidación) | B12: =CRITERIOS!$B$12 -> 0.1 | C12: CRITERIOS
A13: Recuperación de CH₄ (R) | B13: 0 | C13: Sin captura reportada por los operadores
A14: Primer año de disposición | B14: =CRITERIOS!$B$15 -> 2001 | C14: CRITERIOS
A15: Crecimiento poblacional anual | B15: 0.013 | C15: PDM 2024 (1.3 % anual)
A16: Generación per cápita | B16: =SUPUESTOS_FE!$B$28 -> 0.81 | C16: SUPUESTOS_FE (constante en la serie)
A17: Fracción a relleno | B17: =CRITERIOS!$B$11 -> 1 | C17: CRITERIOS
A18: Control: suma de fracciones degradables | B18: =SUM(B5:G5) -> 0.7767
A20: Año | B20: Población | C20: RSU a relleno (t) | D20: Alimentos dep. | E20: Alimentos acum. | F20: Alimentos descomp. | G20: Jardinería dep. | H20: Jardinería acum. | I20: Jardinería descomp. | J20: Papel y cartón dep. | K20: Papel y cartón acum. | L20: Papel y cartón descomp. | M20: Madera dep. | N20: Madera acum. | O20: Madera descomp. | P20: Textiles dep. | Q20: Textiles acum. | R20: Textiles descomp. | S20: Pañales dep. | T20: Pañales acum. | U20: Pañales descomp. | V20: DDOCm descomp. total | W20: CH₄ generado (t) | X20: CH₄ emitido (t) | Y20: E total (tCO₂e) | Z20: RSU a La Loma (t) | AA20: La Loma Alimentos dep. | AB20: La Loma Alimentos acum. | AC20: La Loma Jardinería dep. | AD20: La Loma Jardinería acum. | AE20: La Loma Papel y cartón dep. | AF20: La Loma Papel y cartón acum. | AG20: La Loma Madera dep. | AH20: La Loma Madera acum. | AI20: La Loma Textiles dep. | AJ20: La Loma Textiles acum. | AK20: La Loma Pañales dep. | AL20: La Loma Pañales acum. | AM20: La Loma DDOCm descomp. | AN20: E La Loma (tCO₂e) | AO20: E San Nicolás (tCO₂e)
A21: 1990 | B21: =SUPUESTOS_FE!$B$5*(1+$B$15)^(A21-2022) -> 31515.5 | C21: =IF(A21>=$B$14,B21*$B$16*365/1000*$B$17,0) -> 0 | D21: =C21*$B$5*$B$6*$B$9*$B$10 -> 0 | E21: =D21 -> 0 | F21: 0 | G21: =C21*$C$5*$C$6*$B$9*$B$10 -> 0 | H21: =G21 -> 0 | I21: 0 | J21: =C21*$D$5*$D$6*$B$9*$B$10 -> 0 | K21: =J21 -> 0 | L21: 0 | M21: =C21*$E$5*$E$6*$B$9*$B$10 -> 0 | N21: =M21 -> 0 | O21: 0 | P21: =C21*$F$5*$F$6*$B$9*$B$10 -> 0 | Q21: =P21 -> 0 | R21: 0 | S21: =C21*$G$5*$G$6*$B$9*$B$10 -> 0 | T21: =S21 -> 0 | U21: 0 | V21: =F21+I21+L21+O21+R21+U21 -> 0 | W21: =V21*$B$11*16/12 -> 0 | X21: =(W21-$B$13)*(1-$B$12) -> 0 | Y21: =X21*SUPUESTOS_FE!$B$9 -> 0 | Z21: =IF(A21>=CRITERIOS!$B$16,C21,0) -> 0 | AA21: =Z21*$B$5*$B$6*$B$9*$B$10 -> 0 | AB21: =AA21 -> 0 | AC21: =Z21*$C$5*$C$6*$B$9*$B$10 -> 0 | AD21: =AC21 -> 0 | AE21: =Z21*$D$5*$D$6*$B$9*$B$10 -> 0 | AF21: =AE21 -> 0 | AG21: =Z21*$E$5*$E$6*$B$9*$B$10 -> 0 | AH21: =AG21 -> 0 | AI21: =Z21*$F$5*$F$6*$B$9*$B$10 -> 0 | AJ21: =AI21 -> 0 | AK21: =Z21*$G$5*$G$6*$B$9*$B$10 -> 0 | AL21: =AK21 -> 0 | AM21: 0 | AN21: =AM21*$B$11*16/12*(1-$B$12)*SUPUESTOS_FE!$B$9 -> 0 | AO21: =Y21-AN21 -> 0
A22: 1991 | B22: =SUPUESTOS_FE!$B$5*(1+$B$15)^(A22-2022) -> 31925.201 | C22: =IF(A22>=$B$14,B22*$B$16*365/1000*$B$17,0) -> 0 | D22: =C22*$B$5*$B$6*$B$9*$B$10 -> 0 | E22: =D22+E21*EXP(-$B$7) -> 0 | F22: =E21*(1-EXP(-$B$7)) -> 0 | G22: =C22*$C$5*$C$6*$B$9*$B$10 -> 0 | H22: =G22+H21*EXP(-$C$7) -> 0 | I22: =H21*(1-EXP(-$C$7)) -> 0 | J22: =C22*$D$5*$D$6*$B$9*$B$10 -> 0 | K22: =J22+K21*EXP(-$D$7) -> 0 | L22: =K21*(1-EXP(-$D$7)) -> 0 | M22: =C22*$E$5*$E$6*$B$9*$B$10 -> 0 | N22: =M22+N21*EXP(-$E$7) -> 0 | O22: =N21*(1-EXP(-$E$7)) -> 0 | P22: =C22*$F$5*$F$6*$B$9*$B$10 -> 0 | Q22: =P22+Q21*EXP(-$F$7) -> 0 | R22: =Q21*(1-EXP(-$F$7)) -> 0 | S22: =C22*$G$5*$G$6*$B$9*$B$10 -> 0 | T22: =S22+T21*EXP(-$G$7) -> 0 | U22: =T21*(1-EXP(-$G$7)) -> 0 | V22: =F22+I22+L22+O22+R22+U22 -> 0 | W22: =V22*$B$11*16/12 -> 0 | X22: =(W22-$B$13)*(1-$B$12) -> 0 | Y22: =X22*SUPUESTOS_FE!$B$9 -> 0 | Z22: =IF(A22>=CRITERIOS!$B$16,C22,0) -> 0 | AA22: =Z22*$B$5*$B$6*$B$9*$B$10 -> 0 | AB22: =AA22+AB21*EXP(-$B$7) -> 0 | AC22: =Z22*$C$5*$C$6*$B$9*$B$10 -> 0 | AD22: =AC22+AD21*EXP(-$C$7) -> 0 | AE22: =Z22*$D$5*$D$6*$B$9*$B$10 -> 0 | AF22: =AE22+AF21*EXP(-$D$7) -> 0 | AG22: =Z22*$E$5*$E$6*$B$9*$B$10 -> 0 | AH22: =AG22+AH21*EXP(-$E$7) -> 0 | AI22: =Z22*$F$5*$F$6*$B$9*$B$10 -> 0 | AJ22: =AI22+AJ21*EXP(-$F$7) -> 0 | AK22: =Z22*$G$5*$G$6*$B$9*$B$10 -> 0 | AL22: =AK22+AL21*EXP(-$G$7) -> 0 | AM22: =AB21*(1-EXP(-$B$7))+AD21*(1-EXP(-$C$7))+AF21*(1-EXP(-$D$7))+AH21*(1-EXP(-$E$7))+AJ21*(1-EXP(-$F$7))+AL21*(1-EXP(-$G$7)) -> 0 | AN22: =AM22*$B$11*16/12*(1-$B$12)*SUPUESTOS_FE!$B$9 -> 0 | AO22: =Y22-AN22 -> 0
A23: 1992 | B23: =SUPUESTOS_FE!$B$5*(1+$B$15)^(A23-2022) -> 32340.229 | C23: =IF(A23>=$B$14,B23*$B$16*365/1000*$B$17,0) -> 0 | D23: =C23*$B$5*$B$6*$B$9*$B$10 -> 0 | E23: =D23+E22*EXP(-$B$7) -> 0 | F23: =E22*(1-EXP(-$B$7)) -> 0 | G23: =C23*$C$5*$C$6*$B$9*$B$10 -> 0 | H23: =G23+H22*EXP(-$C$7) -> 0 | I23: =H22*(1-EXP(-$C$7)) -> 0 | J23: =C23*$D$5*$D$6*$B$9*$B$10 -> 0 | K23: =J23+K22*EXP(-$D$7) -> 0 | L23: =K22*(1-EXP(-$D$7)) -> 0 | M23: =C23*$E$5*$E$6*$B$9*$B$10 -> 0 | N23: =M23+N22*EXP(-$E$7) -> 0 | O23: =N22*(1-EXP(-$E$7)) -> 0 | P23: =C23*$F$5*$F$6*$B$9*$B$10 -> 0 | Q23: =P23+Q22*EXP(-$F$7) -> 0 | R23: =Q22*(1-EXP(-$F$7)) -> 0 | S23: =C23*$G$5*$G$6*$B$9*$B$10 -> 0 | T23: =S23+T22*EXP(-$G$7) -> 0 | U23: =T22*(1-EXP(-$G$7)) -> 0 | V23: =F23+I23+L23+O23+R23+U23 -> 0 | W23: =V23*$B$11*16/12 -> 0 | X23: =(W23-$B$13)*(1-$B$12) -> 0 | Y23: =X23*SUPUESTOS_FE!$B$9 -> 0 | Z23: =IF(A23>=CRITERIOS!$B$16,C23,0) -> 0 | AA23: =Z23*$B$5*$B$6*$B$9*$B$10 -> 0 | AB23: =AA23+AB22*EXP(-$B$7) -> 0 | AC23: =Z23*$C$5*$C$6*$B$9*$B$10 -> 0 | AD23: =AC23+AD22*EXP(-$C$7) -> 0 | AE23: =Z23*$D$5*$D$6*$B$9*$B$10 -> 0 | AF23: =AE23+AF22*EXP(-$D$7) -> 0 | AG23: =Z23*$E$5*$E$6*$B$9*$B$10 -> 0 | AH23: =AG23+AH22*EXP(-$E$7) -> 0 | AI23: =Z23*$F$5*$F$6*$B$9*$B$10 -> 0 | AJ23: =AI23+AJ22*EXP(-$F$7) -> 0 | AK23: =Z23*$G$5*$G$6*$B$9*$B$10 -> 0 | AL23: =AK23+AL22*EXP(-$G$7) -> 0 | AM23: =AB22*(1-EXP(-$B$7))+AD22*(1-EXP(-$C$7))+AF22*(1-EXP(-$D$7))+AH22*(1-EXP(-$E$7))+AJ22*(1-EXP(-$F$7))+AL22*(1-EXP(-$G$7)) -> 0 | AN23: =AM23*$B$11*16/12*(1-$B$12)*SUPUESTOS_FE!$B$9 -> 0 | AO23: =Y23-AN23 -> 0
A24: 1993 | B24: =SUPUESTOS_FE!$B$5*(1+$B$15)^(A24-2022) -> 32760.652 | C24: =IF(A24>=$B$14,B24*$B$16*365/1000*$B$17,0) -> 0 | D24: =C24*$B$5*$B$6*$B$9*$B$10 -> 0 | E24: =D24+E23*EXP(-$B$7) -> 0 | F24: =E23*(1-EXP(-$B$7)) -> 0 | G24: =C24*$C$5*$C$6*$B$9*$B$10 -> 0 | H24: =G24+H23*EXP(-$C$7) -> 0 | I24: =H23*(1-EXP(-$C$7)) -> 0 | J24: =C24*$D$5*$D$6*$B$9*$B$10 -> 0 | K24: =J24+K23*EXP(-$D$7) -> 0 | L24: =K23*(1-EXP(-$D$7)) -> 0 | M24: =C24*$E$5*$E$6*$B$9*$B$10 -> 0 | N24: =M24+N23*EXP(-$E$7) -> 0 | O24: =N23*(1-EXP(-$E$7)) -> 0 | P24: =C24*$F$5*$F$6*$B$9*$B$10 -> 0 | Q24: =P24+Q23*EXP(-$F$7) -> 0 | R24: =Q23*(1-EXP(-$F$7)) -> 0 | S24: =C24*$G$5*$G$6*$B$9*$B$10 -> 0 | T24: =S24+T23*EXP(-$G$7) -> 0 | U24: =T23*(1-EXP(-$G$7)) -> 0 | V24: =F24+I24+L24+O24+R24+U24 -> 0 | W24: =V24*$B$11*16/12 -> 0 | X24: =(W24-$B$13)*(1-$B$12) -> 0 | Y24: =X24*SUPUESTOS_FE!$B$9 -> 0 | Z24: =IF(A24>=CRITERIOS!$B$16,C24,0) -> 0 | AA24: =Z24*$B$5*$B$6*$B$9*$B$10 -> 0 | AB24: =AA24+AB23*EXP(-$B$7) -> 0 | AC24: =Z24*$C$5*$C$6*$B$9*$B$10 -> 0 | AD24: =AC24+AD23*EXP(-$C$7) -> 0 | AE24: =Z24*$D$5*$D$6*$B$9*$B$10 -> 0 | AF24: =AE24+AF23*EXP(-$D$7) -> 0 | AG24: =Z24*$E$5*$E$6*$B$9*$B$10 -> 0 | AH24: =AG24+AH23*EXP(-$E$7) -> 0 | AI24: =Z24*$F$5*$F$6*$B$9*$B$10 -> 0 | AJ24: =AI24+AJ23*EXP(-$F$7) -> 0 | AK24: =Z24*$G$5*$G$6*$B$9*$B$10 -> 0 | AL24: =AK24+AL23*EXP(-$G$7) -> 0 | AM24: =AB23*(1-EXP(-$B$7))+AD23*(1-EXP(-$C$7))+AF23*(1-EXP(-$D$7))+AH23*(1-EXP(-$E$7))+AJ23*(1-EXP(-$F$7))+AL23*(1-EXP(-$G$7)) -> 0 | AN24: =AM24*$B$11*16/12*(1-$B$12)*SUPUESTOS_FE!$B$9 -> 0 | AO24: =Y24-AN24 -> 0
A25: 1994 | B25: =SUPUESTOS_FE!$B$5*(1+$B$15)^(A25-2022) -> 33186.54 | C25: =IF(A25>=$B$14,B25*$B$16*365/1000*$B$17,0) -> 0 | D25: =C25*$B$5*$B$6*$B$9*$B$10 -> 0 | E25: =D25+E24*EXP(-$B$7) -> 0 | F25: =E24*(1-EXP(-$B$7)) -> 0 | G25: =C25*$C$5*$C$6*$B$9*$B$10 -> 0 | H25: =G25+H24*EXP(-$C$7) -> 0 | I25: =H24*(1-EXP(-$C$7)) -> 0 | J25: =C25*$D$5*$D$6*$B$9*$B$10 -> 0 | K25: =J25+K24*EXP(-$D$7) -> 0 | L25: =K24*(1-EXP(-$D$7)) -> 0 | M25: =C25*$E$5*$E$6*$B$9*$B$10 -> 0 | N25: =M25+N24*EXP(-$E$7) -> 0 | O25: =N24*(1-EXP(-$E$7)) -> 0 | P25: =C25*$F$5*$F$6*$B$9*$B$10 -> 0 | Q25: =P25+Q24*EXP(-$F$7) -> 0 | R25: =Q24*(1-EXP(-$F$7)) -> 0 | S25: =C25*$G$5*$G$6*$B$9*$B$10 -> 0 | T25: =S25+T24*EXP(-$G$7) -> 0 | U25: =T24*(1-EXP(-$G$7)) -> 0 | V25: =F25+I25+L25+O25+R25+U25 -> 0 | W25: =V25*$B$11*16/12 -> 0 | X25: =(W25-$B$13)*(1-$B$12) -> 0 | Y25: =X25*SUPUESTOS_FE!$B$9 -> 0 | Z25: =IF(A25>=CRITERIOS!$B$16,C25,0) -> 0 | AA25: =Z25*$B$5*$B$6*$B$9*$B$10 -> 0 | AB25: =AA25+AB24*EXP(-$B$7) -> 0 | AC25: =Z25*$C$5*$C$6*$B$9*$B$10 -> 0 | AD25: =AC25+AD24*EXP(-$C$7) -> 0 | AE25: =Z25*$D$5*$D$6*$B$9*$B$10 -> 0 | AF25: =AE25+AF24*EXP(-$D$7) -> 0 | AG25: =Z25*$E$5*$E$6*$B$9*$B$10 -> 0 | AH25: =AG25+AH24*EXP(-$E$7) -> 0 | AI25: =Z25*$F$5*$F$6*$B$9*$B$10 -> 0 | AJ25: =AI25+AJ24*EXP(-$F$7) -> 0 | AK25: =Z25*$G$5*$G$6*$B$9*$B$10 -> 0 | AL25: =AK25+AL24*EXP(-$G$7) -> 0 | AM25: =AB24*(1-EXP(-$B$7))+AD24*(1-EXP(-$C$7))+AF24*(1-EXP(-$D$7))+AH24*(1-EXP(-$E$7))+AJ24*(1-EXP(-$F$7))+AL24*(1-EXP(-$G$7)) -> 0 | AN25: =AM25*$B$11*16/12*(1-$B$12)*SUPUESTOS_FE!$B$9 -> 0 | AO25: =Y25-AN25 -> 0
A26: 1995 | B26: =SUPUESTOS_FE!$B$5*(1+$B$15)^(A26-2022) -> 33617.965 | C26: =IF(A26>=$B$14,B26*$B$16*365/1000*$B$17,0) -> 0 | D26: =C26*$B$5*$B$6*$B$9*$B$10 -> 0 | E26: =D26+E25*EXP(-$B$7) -> 0 | F26: =E25*(1-EXP(-$B$7)) -> 0 | G26: =C26*$C$5*$C$6*$B$9*$B$10 -> 0 | H26: =G26+H25*EXP(-$C$7) -> 0 | I26: =H25*(1-EXP(-$C$7)) -> 0 | J26: =C26*$D$5*$D$6*$B$9*$B$10 -> 0 | K26: =J26+K25*EXP(-$D$7) -> 0 | L26: =K25*(1-EXP(-$D$7)) -> 0 | M26: =C26*$E$5*$E$6*$B$9*$B$10 -> 0 | N26: =M26+N25*EXP(-$E$7) -> 0 | O26: =N25*(1-EXP(-$E$7)) -> 0 | P26: =C26*$F$5*$F$6*$B$9*$B$10 -> 0 | Q26: =P26+Q25*EXP(-$F$7) -> 0 | R26: =Q25*(1-EXP(-$F$7)) -> 0 | S26: =C26*$G$5*$G$6*$B$9*$B$10 -> 0 | T26: =S26+T25*EXP(-$G$7) -> 0 | U26: =T25*(1-EXP(-$G$7)) -> 0 | V26: =F26+I26+L26+O26+R26+U26 -> 0 | W26: =V26*$B$11*16/12 -> 0 | X26: =(W26-$B$13)*(1-$B$12) -> 0 | Y26: =X26*SUPUESTOS_FE!$B$9 -> 0 | Z26: =IF(A26>=CRITERIOS!$B$16,C26,0) -> 0 | AA26: =Z26*$B$5*$B$6*$B$9*$B$10 -> 0 | AB26: =AA26+AB25*EXP(-$B$7) -> 0 | AC26: =Z26*$C$5*$C$6*$B$9*$B$10 -> 0 | AD26: =AC26+AD25*EXP(-$C$7) -> 0 | AE26: =Z26*$D$5*$D$6*$B$9*$B$10 -> 0 | AF26: =AE26+AF25*EXP(-$D$7) -> 0 | AG26: =Z26*$E$5*$E$6*$B$9*$B$10 -> 0 | AH26: =AG26+AH25*EXP(-$E$7) -> 0 | AI26: =Z26*$F$5*$F$6*$B$9*$B$10 -> 0 | AJ26: =AI26+AJ25*EXP(-$F$7) -> 0 | AK26: =Z26*$G$5*$G$6*$B$9*$B$10 -> 0 | AL26: =AK26+AL25*EXP(-$G$7) -> 0 | AM26: =AB25*(1-EXP(-$B$7))+AD25*(1-EXP(-$C$7))+AF25*(1-EXP(-$D$7))+AH25*(1-EXP(-$E$7))+AJ25*(1-EXP(-$F$7))+AL25*(1-EXP(-$G$7)) -> 0 | AN26: =AM26*$B$11*16/12*(1-$B$12)*SUPUESTOS_FE!$B$9 -> 0 | AO26: =Y26-AN26 -> 0
A27: 1996 | B27: =SUPUESTOS_FE!$B$5*(1+$B$15)^(A27-2022) -> 34054.999 | C27: =IF(A27>=$B$14,B27*$B$16*365/1000*$B$17,0) -> 0 | D27: =C27*$B$5*$B$6*$B$9*$B$10 -> 0 | E27: =D27+E26*EXP(-$B$7) -> 0 | F27: =E26*(1-EXP(-$B$7)) -> 0 | G27: =C27*$C$5*$C$6*$B$9*$B$10 -> 0 | H27: =G27+H26*EXP(-$C$7) -> 0 | I27: =H26*(1-EXP(-$C$7)) -> 0 | J27: =C27*$D$5*$D$6*$B$9*$B$10 -> 0 | K27: =J27+K26*EXP(-$D$7) -> 0 | L27: =K26*(1-EXP(-$D$7)) -> 0 | M27: =C27*$E$5*$E$6*$B$9*$B$10 -> 0 | N27: =M27+N26*EXP(-$E$7) -> 0 | O27: =N26*(1-EXP(-$E$7)) -> 0 | P27: =C27*$F$5*$F$6*$B$9*$B$10 -> 0 | Q27: =P27+Q26*EXP(-$F$7) -> 0 | R27: =Q26*(1-EXP(-$F$7)) -> 0 | S27: =C27*$G$5*$G$6*$B$9*$B$10 -> 0 | T27: =S27+T26*EXP(-$G$7) -> 0 | U27: =T26*(1-EXP(-$G$7)) -> 0 | V27: =F27+I27+L27+O27+R27+U27 -> 0 | W27: =V27*$B$11*16/12 -> 0 | X27: =(W27-$B$13)*(1-$B$12) -> 0 | Y27: =X27*SUPUESTOS_FE!$B$9 -> 0 | Z27: =IF(A27>=CRITERIOS!$B$16,C27,0) -> 0 | AA27: =Z27*$B$5*$B$6*$B$9*$B$10 -> 0 | AB27: =AA27+AB26*EXP(-$B$7) -> 0 | AC27: =Z27*$C$5*$C$6*$B$9*$B$10 -> 0 | AD27: =AC27+AD26*EXP(-$C$7) -> 0 | AE27: =Z27*$D$5*$D$6*$B$9*$B$10 -> 0 | AF27: =AE27+AF26*EXP(-$D$7) -> 0 | AG27: =Z27*$E$5*$E$6*$B$9*$B$10 -> 0 | AH27: =AG27+AH26*EXP(-$E$7) -> 0 | AI27: =Z27*$F$5*$F$6*$B$9*$B$10 -> 0 | AJ27: =AI27+AJ26*EXP(-$F$7) -> 0 | AK27: =Z27*$G$5*$G$6*$B$9*$B$10 -> 0 | AL27: =AK27+AL26*EXP(-$G$7) -> 0 | AM27: =AB26*(1-EXP(-$B$7))+AD26*(1-EXP(-$C$7))+AF26*(1-EXP(-$D$7))+AH26*(1-EXP(-$E$7))+AJ26*(1-EXP(-$F$7))+AL26*(1-EXP(-$G$7)) -> 0 | AN27: =AM27*$B$11*16/12*(1-$B$12)*SUPUESTOS_FE!$B$9 -> 0 | AO27: =Y27-AN27 -> 0
A28: 1997 | B28: =SUPUESTOS_FE!$B$5*(1+$B$15)^(A28-2022) -> 34497.714 | C28: =IF(A28>=$B$14,B28*$B$16*365/1000*$B$17,0) -> 0 | D28: =C28*$B$5*$B$6*$B$9*$B$10 -> 0 | E28: =D28+E27*EXP(-$B$7) -> 0 | F28: =E27*(1-EXP(-$B$7)) -> 0 | G28: =C28*$C$5*$C$6*$B$9*$B$10 -> 0 | H28: =G28+H27*EXP(-$C$7) -> 0 | I28: =H27*(1-EXP(-$C$7)) -> 0 | J28: =C28*$D$5*$D$6*$B$9*$B$10 -> 0 | K28: =J28+K27*EXP(-$D$7) -> 0 | L28: =K27*(1-EXP(-$D$7)) -> 0 | M28: =C28*$E$5*$E$6*$B$9*$B$10 -> 0 | N28: =M28+N27*EXP(-$E$7) -> 0 | O28: =N27*(1-EXP(-$E$7)) -> 0 | P28: =C28*$F$5*$F$6*$B$9*$B$10 -> 0 | Q28: =P28+Q27*EXP(-$F$7) -> 0 | R28: =Q27*(1-EXP(-$F$7)) -> 0 | S28: =C28*$G$5*$G$6*$B$9*$B$10 -> 0 | T28: =S28+T27*EXP(-$G$7) -> 0 | U28: =T27*(1-EXP(-$G$7)) -> 0 | V28: =F28+I28+L28+O28+R28+U28 -> 0 | W28: =V28*$B$11*16/12 -> 0 | X28: =(W28-$B$13)*(1-$B$12) -> 0 | Y28: =X28*SUPUESTOS_FE!$B$9 -> 0 | Z28: =IF(A28>=CRITERIOS!$B$16,C28,0) -> 0 | AA28: =Z28*$B$5*$B$6*$B$9*$B$10 -> 0 | AB28: =AA28+AB27*EXP(-$B$7) -> 0 | AC28: =Z28*$C$5*$C$6*$B$9*$B$10 -> 0 | AD28: =AC28+AD27*EXP(-$C$7) -> 0 | AE28: =Z28*$D$5*$D$6*$B$9*$B$10 -> 0 | AF28: =AE28+AF27*EXP(-$D$7) -> 0 | AG28: =Z28*$E$5*$E$6*$B$9*$B$10 -> 0 | AH28: =AG28+AH27*EXP(-$E$7) -> 0 | AI28: =Z28*$F$5*$F$6*$B$9*$B$10 -> 0 | AJ28: =AI28+AJ27*EXP(-$F$7) -> 0 | AK28: =Z28*$G$5*$G$6*$B$9*$B$10 -> 0 | AL28: =AK28+AL27*EXP(-$G$7) -> 0 | AM28: =AB27*(1-EXP(-$B$7))+AD27*(1-EXP(-$C$7))+AF27*(1-EXP(-$D$7))+AH27*(1-EXP(-$E$7))+AJ27*(1-EXP(-$F$7))+AL27*(1-EXP(-$G$7)) -> 0 | AN28: =AM28*$B$11*16/12*(1-$B$12)*SUPUESTOS_FE!$B$9 -> 0 | AO28: =Y28-AN28 -> 0
A29: 1998 | B29: =SUPUESTOS_FE!$B$5*(1+$B$15)^(A29-2022) -> 34946.184 | C29: =IF(A29>=$B$14,B29*$B$16*365/1000*$B$17,0) -> 0 | D29: =C29*$B$5*$B$6*$B$9*$B$10 -> 0 | E29: =D29+E28*EXP(-$B$7) -> 0 | F29: =E28*(1-EXP(-$B$7)) -> 0 | G29: =C29*$C$5*$C$6*$B$9*$B$10 -> 0 | H29: =G29+H28*EXP(-$C$7) -> 0 | I29: =H28*(1-EXP(-$C$7)) -> 0 | J29: =C29*$D$5*$D$6*$B$9*$B$10 -> 0 | K29: =J29+K28*EXP(-$D$7) -> 0 | L29: =K28*(1-EXP(-$D$7)) -> 0 | M29: =C29*$E$5*$E$6*$B$9*$B$10 -> 0 | N29: =M29+N28*EXP(-$E$7) -> 0 | O29: =N28*(1-EXP(-$E$7)) -> 0 | P29: =C29*$F$5*$F$6*$B$9*$B$10 -> 0 | Q29: =P29+Q28*EXP(-$F$7) -> 0 | R29: =Q28*(1-EXP(-$F$7)) -> 0 | S29: =C29*$G$5*$G$6*$B$9*$B$10 -> 0 | T29: =S29+T28*EXP(-$G$7) -> 0 | U29: =T28*(1-EXP(-$G$7)) -> 0 | V29: =F29+I29+L29+O29+R29+U29 -> 0 | W29: =V29*$B$11*16/12 -> 0 | X29: =(W29-$B$13)*(1-$B$12) -> 0 | Y29: =X29*SUPUESTOS_FE!$B$9 -> 0 | Z29: =IF(A29>=CRITERIOS!$B$16,C29,0) -> 0 | AA29: =Z29*$B$5*$B$6*$B$9*$B$10 -> 0 | AB29: =AA29+AB28*EXP(-$B$7) -> 0 | AC29: =Z29*$C$5*$C$6*$B$9*$B$10 -> 0 | AD29: =AC29+AD28*EXP(-$C$7) -> 0 | AE29: =Z29*$D$5*$D$6*$B$9*$B$10 -> 0 | AF29: =AE29+AF28*EXP(-$D$7) -> 0 | AG29: =Z29*$E$5*$E$6*$B$9*$B$10 -> 0 | AH29: =AG29+AH28*EXP(-$E$7) -> 0 | AI29: =Z29*$F$5*$F$6*$B$9*$B$10 -> 0 | AJ29: =AI29+AJ28*EXP(-$F$7) -> 0 | AK29: =Z29*$G$5*$G$6*$B$9*$B$10 -> 0 | AL29: =AK29+AL28*EXP(-$G$7) -> 0 | AM29: =AB28*(1-EXP(-$B$7))+AD28*(1-EXP(-$C$7))+AF28*(1-EXP(-$D$7))+AH28*(1-EXP(-$E$7))+AJ28*(1-EXP(-$F$7))+AL28*(1-EXP(-$G$7)) -> 0 | AN29: =AM29*$B$11*16/12*(1-$B$12)*SUPUESTOS_FE!$B$9 -> 0 | AO29: =Y29-AN29 -> 0
A30: 1999 | B30: =SUPUESTOS_FE!$B$5*(1+$B$15)^(A30-2022) -> 35400.484 | C30: =IF(A30>=$B$14,B30*$B$16*365/1000*$B$17,0) -> 0 | D30: =C30*$B$5*$B$6*$B$9*$B$10 -> 0 | E30: =D30+E29*EXP(-$B$7) -> 0 | F30: =E29*(1-EXP(-$B$7)) -> 0 | G30: =C30*$C$5*$C$6*$B$9*$B$10 -> 0 | H30: =G30+H29*EXP(-$C$7) -> 0 | I30: =H29*(1-EXP(-$C$7)) -> 0 | J30: =C30*$D$5*$D$6*$B$9*$B$10 -> 0 | K30: =J30+K29*EXP(-$D$7) -> 0 | L30: =K29*(1-EXP(-$D$7)) -> 0 | M30: =C30*$E$5*$E$6*$B$9*$B$10 -> 0 | N30: =M30+N29*EXP(-$E$7) -> 0 | O30: =N29*(1-EXP(-$E$7)) -> 0 | P30: =C30*$F$5*$F$6*$B$9*$B$10 -> 0 | Q30: =P30+Q29*EXP(-$F$7) -> 0 | R30: =Q29*(1-EXP(-$F$7)) -> 0 | S30: =C30*$G$5*$G$6*$B$9*$B$10 -> 0 | T30: =S30+T29*EXP(-$G$7) -> 0 | U30: =T29*(1-EXP(-$G$7)) -> 0 | V30: =F30+I30+L30+O30+R30+U30 -> 0 | W30: =V30*$B$11*16/12 -> 0 | X30: =(W30-$B$13)*(1-$B$12) -> 0 | Y30: =X30*SUPUESTOS_FE!$B$9 -> 0 | Z30: =IF(A30>=CRITERIOS!$B$16,C30,0) -> 0 | AA30: =Z30*$B$5*$B$6*$B$9*$B$10 -> 0 | AB30: =AA30+AB29*EXP(-$B$7) -> 0 | AC30: =Z30*$C$5*$C$6*$B$9*$B$10 -> 0 | AD30: =AC30+AD29*EXP(-$C$7) -> 0 | AE30: =Z30*$D$5*$D$6*$B$9*$B$10 -> 0 | AF30: =AE30+AF29*EXP(-$D$7) -> 0 | AG30: =Z30*$E$5*$E$6*$B$9*$B$10 -> 0 | AH30: =AG30+AH29*EXP(-$E$7) -> 0 | AI30: =Z30*$F$5*$F$6*$B$9*$B$10 -> 0 | AJ30: =AI30+AJ29*EXP(-$F$7) -> 0 | AK30: =Z30*$G$5*$G$6*$B$9*$B$10 -> 0 | AL30: =AK30+AL29*EXP(-$G$7) -> 0 | AM30: =AB29*(1-EXP(-$B$7))+AD29*(1-EXP(-$C$7))+AF29*(1-EXP(-$D$7))+AH29*(1-EXP(-$E$7))+AJ29*(1-EXP(-$F$7))+AL29*(1-EXP(-$G$7)) -> 0 | AN30: =AM30*$B$11*16/12*(1-$B$12)*SUPUESTOS_FE!$B$9 -> 0 | AO30: =Y30-AN30 -> 0
A31: 2000 | B31: =SUPUESTOS_FE!$B$5*(1+$B$15)^(A31-2022) -> 35860.691 | C31: =IF(A31>=$B$14,B31*$B$16*365/1000*$B$17,0) -> 0 | D31: =C31*$B$5*$B$6*$B$9*$B$10 -> 0 | E31: =D31+E30*EXP(-$B$7) -> 0 | F31: =E30*(1-EXP(-$B$7)) -> 0 | G31: =C31*$C$5*$C$6*$B$9*$B$10 -> 0 | H31: =G31+H30*EXP(-$C$7) -> 0 | I31: =H30*(1-EXP(-$C$7)) -> 0 | J31: =C31*$D$5*$D$6*$B$9*$B$10 -> 0 | K31: =J31+K30*EXP(-$D$7) -> 0 | L31: =K30*(1-EXP(-$D$7)) -> 0 | M31: =C31*$E$5*$E$6*$B$9*$B$10 -> 0 | N31: =M31+N30*EXP(-$E$7) -> 0 | O31: =N30*(1-EXP(-$E$7)) -> 0 | P31: =C31*$F$5*$F$6*$B$9*$B$10 -> 0 | Q31: =P31+Q30*EXP(-$F$7) -> 0 | R31: =Q30*(1-EXP(-$F$7)) -> 0 | S31: =C31*$G$5*$G$6*$B$9*$B$10 -> 0 | T31: =S31+T30*EXP(-$G$7) -> 0 | U31: =T30*(1-EXP(-$G$7)) -> 0 | V31: =F31+I31+L31+O31+R31+U31 -> 0 | W31: =V31*$B$11*16/12 -> 0 | X31: =(W31-$B$13)*(1-$B$12) -> 0 | Y31: =X31*SUPUESTOS_FE!$B$9 -> 0 | Z31: =IF(A31>=CRITERIOS!$B$16,C31,0) -> 0 | AA31: =Z31*$B$5*$B$6*$B$9*$B$10 -> 0 | AB31: =AA31+AB30*EXP(-$B$7) -> 0 | AC31: =Z31*$C$5*$C$6*$B$9*$B$10 -> 0 | AD31: =AC31+AD30*EXP(-$C$7) -> 0 | AE31: =Z31*$D$5*$D$6*$B$9*$B$10 -> 0 | AF31: =AE31+AF30*EXP(-$D$7) -> 0 | AG31: =Z31*$E$5*$E$6*$B$9*$B$10 -> 0 | AH31: =AG31+AH30*EXP(-$E$7) -> 0 | AI31: =Z31*$F$5*$F$6*$B$9*$B$10 -> 0 | AJ31: =AI31+AJ30*EXP(-$F$7) -> 0 | AK31: =Z31*$G$5*$G$6*$B$9*$B$10 -> 0 | AL31: =AK31+AL30*EXP(-$G$7) -> 0 | AM31: =AB30*(1-EXP(-$B$7))+AD30*(1-EXP(-$C$7))+AF30*(1-EXP(-$D$7))+AH30*(1-EXP(-$E$7))+AJ30*(1-EXP(-$F$7))+AL30*(1-EXP(-$G$7)) -> 0 | AN31: =AM31*$B$11*16/12*(1-$B$12)*SUPUESTOS_FE!$B$9 -> 0 | AO31: =Y31-AN31 -> 0
A32: 2001 | B32: =SUPUESTOS_FE!$B$5*(1+$B$15)^(A32-2022) -> 36326.88 | C32: =IF(A32>=$B$14,B32*$B$16*365/1000*$B$17,0) -> 10740.042 | D32: =C32*$B$5*$B$6*$B$9*$B$10 -> 295.29745 | E32: =D32+E31*EXP(-$B$7) -> 295.29745 | F32: =E31*(1-EXP(-$B$7)) -> 0 | G32: =C32*$C$5*$C$6*$B$9*$B$10 -> 157.87862 | H32: =G32+H31*EXP(-$C$7) -> 157.87862 | I32: =H31*(1-EXP(-$C$7)) -> 0 | J32: =C32*$D$5*$D$6*$B$9*$B$10 -> 334.87451 | K32: =J32+K31*EXP(-$D$7) -> 334.87451 | L32: =K31*(1-EXP(-$D$7)) -> 0 | M32: =C32*$E$5*$E$6*$B$9*$B$10 -> 6.4655052 | N32: =M32+N31*EXP(-$E$7) -> 6.4655052 | O32: =N31*(1-EXP(-$E$7)) -> 0 | P32: =C32*$F$5*$F$6*$B$9*$B$10 -> 13.145811 | Q32: =P32+Q31*EXP(-$F$7) -> 13.145811 | R32: =Q31*(1-EXP(-$F$7)) -> 0 | S32: =C32*$G$5*$G$6*$B$9*$B$10 -> 121.40543 | T32: =S32+T31*EXP(-$G$7) -> 121.40543 | U32: =T31*(1-EXP(-$G$7)) -> 0 | V32: =F32+I32+L32+O32+R32+U32 -> 0 | W32: =V32*$B$11*16/12 -> 0 | X32: =(W32-$B$13)*(1-$B$12) -> 0 | Y32: =X32*SUPUESTOS_FE!$B$9 -> 0 | Z32: =IF(A32>=CRITERIOS!$B$16,C32,0) -> 0 | AA32: =Z32*$B$5*$B$6*$B$9*$B$10 -> 0 | AB32: =AA32+AB31*EXP(-$B$7) -> 0 | AC32: =Z32*$C$5*$C$6*$B$9*$B$10 -> 0 | AD32: =AC32+AD31*EXP(-$C$7) -> 0 | AE32: =Z32*$D$5*$D$6*$B$9*$B$10 -> 0 | AF32: =AE32+AF31*EXP(-$D$7) -> 0 | AG32: =Z32*$E$5*$E$6*$B$9*$B$10 -> 0 | AH32: =AG32+AH31*EXP(-$E$7) -> 0 | AI32: =Z32*$F$5*$F$6*$B$9*$B$10 -> 0 | AJ32: =AI32+AJ31*EXP(-$F$7) -> 0 | AK32: =Z32*$G$5*$G$6*$B$9*$B$10 -> 0 | AL32: =AK32+AL31*EXP(-$G$7) -> 0 | AM32: =AB31*(1-EXP(-$B$7))+AD31*(1-EXP(-$C$7))+AF31*(1-EXP(-$D$7))+AH31*(1-EXP(-$E$7))+AJ31*(1-EXP(-$F$7))+AL31*(1-EXP(-$G$7)) -> 0 | AN32: =AM32*$B$11*16/12*(1-$B$12)*SUPUESTOS_FE!$B$9 -> 0 | AO32: =Y32-AN32 -> 0
A33: 2002 | B33: =SUPUESTOS_FE!$B$5*(1+$B$15)^(A33-2022) -> 36799.129 | C33: =IF(A33>=$B$14,B33*$B$16*365/1000*$B$17,0) -> 10879.662 | D33: =C33*$B$5*$B$6*$B$9*$B$10 -> 299.13632 | E33: =D33+E32*EXP(-$B$7) -> 577.23699 | F33: =E32*(1-EXP(-$B$7)) -> 17.196785 | G33: =C33*$C$5*$C$6*$B$9*$B$10 -> 159.93104 | H33: =G33+H32*EXP(-$C$7) -> 310.10982 | I33: =H32*(1-EXP(-$C$7)) -> 7.699831 | J33: =C33*$D$5*$D$6*$B$9*$B$10 -> 339.22788 | K33: =J33+K32*EXP(-$D$7) -> 660.97177 | L33: =K32*(1-EXP(-$D$7)) -> 13.130617 | M33: =C33*$E$5*$E$6*$B$9*$B$10 -> 6.5495568 | N33: =M33+N32*EXP(-$E$7) -> 12.887036 | O33: =N32*(1-EXP(-$E$7)) -> 0.12802558 | P33: =C33*$F$5*$F$6*$B$9*$B$10 -> 13.316707 | Q33: =P33+Q32*EXP(-$F$7) -> 25.947064 | R33: =Q32*(1-EXP(-$F$7)) -> 0.51545464 | S33: =C33*$G$5*$G$6*$B$9*$B$10 -> 122.9837 | T33: =S33+T32*EXP(-$G$7) -> 239.62876 | U33: =T32*(1-EXP(-$G$7)) -> 4.7603752 | V33: =F33+I33+L33+O33+R33+U33 -> 43.431089 | W33: =V33*$B$11*16/12 -> 28.954059 | X33: =(W33-$B$13)*(1-$B$12) -> 26.058653 | Y33: =X33*SUPUESTOS_FE!$B$9 -> 729.64229 | Z33: =IF(A33>=CRITERIOS!$B$16,C33,0) -> 0 | AA33: =Z33*$B$5*$B$6*$B$9*$B$10 -> 0 | AB33: =AA33+AB32*EXP(-$B$7) -> 0 | AC33: =Z33*$C$5*$C$6*$B$9*$B$10 -> 0 | AD33: =AC33+AD32*EXP(-$C$7) -> 0 | AE33: =Z33*$D$5*$D$6*$B$9*$B$10 -> 0 | AF33: =AE33+AF32*EXP(-$D$7) -> 0 | AG33: =Z33*$E$5*$E$6*$B$9*$B$10 -> 0 | AH33: =AG33+AH32*EXP(-$E$7) -> 0 | AI33: =Z33*$F$5*$F$6*$B$9*$B$10 -> 0 | AJ33: =AI33+AJ32*EXP(-$F$7) -> 0 | AK33: =Z33*$G$5*$G$6*$B$9*$B$10 -> 0 | AL33: =AK33+AL32*EXP(-$G$7) -> 0 | AM33: =AB32*(1-EXP(-$B$7))+AD32*(1-EXP(-$C$7))+AF32*(1-EXP(-$D$7))+AH32*(1-EXP(-$E$7))+AJ32*(1-EXP(-$F$7))+AL32*(1-EXP(-$G$7)) -> 0 | AN33: =AM33*$B$11*16/12*(1-$B$12)*SUPUESTOS_FE!$B$9 -> 0 | AO33: =Y33-AN33 -> 729.64229
... A61: 2030 | B61: =SUPUESTOS_FE!$B$5*(1+$B$15)^(A61-2022) -> 52832.603 | C61: =IF(A61>=$B$14,B61*$B$16*365/1000*$B$17,0) -> 15619.959 | D61: =C61*$B$5*$B$6*$B$9*$B$10 -> 429.47078 | E61: =D61+E60*EXP(-$B$7) -> 5422.0401 | F61: =E60*(1-EXP(-$B$7)) -> 308.72325 | G61: =C61*$C$5*$C$6*$B$9*$B$10 -> 229.6134 | H61: =G61+H60*EXP(-$C$7) -> 3195.2251 | I61: =H60*(1-EXP(-$C$7)) -> 152.05016 | J61: =C61*$D$5*$D$6*$B$9*$B$10 -> 487.03033 | K61: =J61+K60*EXP(-$D$7) -> 7517.6257 | L61: =K60*(1-EXP(-$D$7)) -> 286.92404 | M61: =C61*$E$5*$E$6*$B$9*$B$10 -> 9.4032154 | N61: =M61+N60*EXP(-$E$7) -> 182.22167 | O61: =N60*(1-EXP(-$E$7)) -> 3.4911645 | P61: =C61*$F$5*$F$6*$B$9*$B$10 -> 19.11883 | Q61: =P61+Q60*EXP(-$F$7) -> 295.11141 | R61: =Q60*(1-EXP(-$F$7)) -> 11.263471 | S61: =C61*$G$5*$G$6*$B$9*$B$10 -> 176.56802 | T61: =S61+T60*EXP(-$G$7) -> 2725.4407 | U61: =T60*(1-EXP(-$G$7)) -> 104.02147 | V61: =F61+I61+L61+O61+R61+U61 -> 866.47355 | W61: =V61*$B$11*16/12 -> 577.64904 | X61: =(W61-$B$13)*(1-$B$12) -> 519.88413 | Y61: =X61*SUPUESTOS_FE!$B$9 -> 14556.756 | Z61: =IF(A61>=CRITERIOS!$B$16,C61,0) -> 15619.959 | AA61: =Z61*$B$5*$B$6*$B$9*$B$10 -> 429.47078 | AB61: =AA61+AB60*EXP(-$B$7) -> 2938.8452 | AC61: =Z61*$C$5*$C$6*$B$9*$B$10 -> 229.6134 | AD61: =AC61+AD60*EXP(-$C$7) -> 1628.0138 | AE61: =Z61*$D$5*$D$6*$B$9*$B$10 -> 487.03033 | AF61: =AE61+AF60*EXP(-$D$7) -> 3580.3005 | AG61: =Z61*$E$5*$E$6*$B$9*$B$10 -> 9.4032154 | AH61: =AG61+AH60*EXP(-$E$7) -> 74.456889 | AI61: =Z61*$F$5*$F$6*$B$9*$B$10 -> 19.11883 | AJ61: =AI61+AJ60*EXP(-$F$7) -> 140.54804 | AK61: =Z61*$G$5*$G$6*$B$9*$B$10 -> 176.56802 | AL61: =AK61+AL60*EXP(-$G$7) -> 1298.0025 | AM61: =AB60*(1-EXP(-$B$7))+AD60*(1-EXP(-$C$7))+AF60*(1-EXP(-$D$7))+AH60*(1-EXP(-$E$7))+AJ60*(1-EXP(-$F$7))+AL60*(1-EXP(-$G$7)) -> 405.14373 | AN61: =AM61*$B$11*16/12*(1-$B$12)*SUPUESTOS_FE!$B$9 -> 6806.4146 | AO61: =Y61-AN61 -> 7750.3411
A63: Columnas «La Loma»: residuos depositados en el CARS La Loma (Tepezalá, operado por PASA) desde 2022; San Nicolás = total − La Loma. Serie con generación per cápita constante y población proyectada con 1.3 % anual. Contraste: el Informe PEPGIR reporta 13,939.35 t dispuestas en La Loma en 2024.

Sheet 4_RESIDUOS
A1: SECTOR 4 — RESIDUOS [4.A / 4.D]
A3: A) RSU en relleno sanitario [4.A] — Alcance 3 GPC (relleno privado extramunicipal); modelo FOD en 4A_RSU_FOD
A4: Concepto | B4: Valor | C4: Unidad | D4: Fórmula / fuente
A5: RSU dispuestos en 2022 | B5: =4A_RSU_FOD!$C$53 -> 14086.54 | C5: t/año | D5: 4A_RSU_FOD
A6: CH₄ emitido en 2022 (FOD) | B6: =4A_RSU_FOD!$X$53 -> 408.46429 | C6: t CH₄/año | D6: Incluye la descomposición de residuos depositados desde el primer año de disposición
A7: Factor implícito | B7: =B6/B5*1000 -> 28.99678 | C7: kgCH₄/t | D7: v1.1 usaba 3.6 kgCH₄/t sin respaldo IPCC (hallazgo M2)
A8: de ello, residuos en San Nicolás (2001–2021) | B8: =4A_RSU_FOD!$Y$53-4A_RSU_FOD!$AN$53 -> 11437 | C8: tCO₂e/año
A9: de ello, residuos en CARS La Loma (2022) | B9: =4A_RSU_FOD!$AN$53 -> 0 | C9: tCO₂e/año | D9: Los residuos de 2022 empiezan a emitir en 2023 (retraso del modelo)
A11: E relleno 2022 | B11: =4A_RSU_FOD!$Y$53 -> 11437 | C11: tCO₂e/año
A13: B) Aguas residuales — CH₄ [4.D] — E = TOW × Bo × MCF por vía × GWP (IPCC 2006 Vol.5 Cap.6)
A14: Concepto | B14: Valor | C14: Unidad | D14: Fórmula / fuente
A15: DBO doméstica total (TOW) | B15: =SUPUESTOS_FE!$B$5*SUPUESTOS_FE!$B$29*365/1000000 -> 939.10266 | C15: t DBO/año | D15: Pob × DBO × 365 / 10⁶
A16: Carga industrial co-descargada | B16: =B15*SUPUESTOS_FE!$B$30 -> 187.82053 | C16: t DBO/año | D16: SUPUESTOS_FE
A17: Cobertura de drenaje | B17: =CRITERIOS!$B$10 -> 0.99 | C17: fracción | D17: CRITERIOS
A18: DBO a PTAR (lodos activados) | B18: =(B15*B17)+B16 -> 1117.5322 | C18: t DBO/año | D18: Doméstica conectada + industrial
A19: DBO sin drenaje (fosa séptica) | B19: =B15*(1-B17) -> 9.3910266 | C19: t DBO/año
A20: Bo | B20: =CRITERIOS!$B$9 -> 0.6 | C20: kgCH₄/kgDBO | D20: CRITERIOS
A21: MCF PTAR | B21: =CRITERIOS!$B$7 -> 0.03 | C21: fracción | D21: CRITERIOS
A22: MCF fosa séptica | B22: =CRITERIOS!$B$8 -> 0.5 | C22: fracción | D22: CRITERIOS
A23: CH₄ PTAR | B23: =B18*B20*B21 -> 20.115579 | C23: t CH₄/año
A24: CH₄ fosa séptica | B24: =B19*B20*B22 -> 2.817308 | C24: t CH₄/año
A25: E CH₄ aguas residuales | B25: =(B23+B24)*SUPUESTOS_FE!$B$9 -> 642.12083 | C25: tCO₂e/año | D25: v1.0: 3.12 (error de unidades, hallazgo C2)
A27: C) Aguas residuales — N₂O [4.D] — E = Pob × N_pc × EF × 44/28 × GWP
A28: Concepto | B28: Valor | C28: Unidad | D28: Fórmula / fuente
A29: N en efluente | B29: =SUPUESTOS_FE!$B$5*SUPUESTOS_FE!$B$31/1000 -> 381.168 | C29: t N/año | D29: Pob × N per cápita / 1000
A30: N₂O efluentes | B30: =B29*SUPUESTOS_FE!$B$32*SUPUESTOS_FE!$B$13 -> 2.9948914 | C30: t N₂O/año | D30: × EF × 44/28
A31: E N₂O aguas residuales | B31: =B30*SUPUESTOS_FE!$B$10 -> 793.64623 | C31: tCO₂e/año | D31: v1.0: 374.75 (faltaba 44/28, hallazgo M1)
A33: TOTAL SECTOR 4 (tCO₂e/año) | B33: =B11+B25+B31 -> 12872.767
A34: CH₄ total del sector = B11 + B25; N₂O = B31.

Sheet 5_IPPU
A1: SECTOR 5 — IPPU [2.F / 2.H / 2.A]
A4: Subcategoría | B4: Dato de actividad | C4: Unidad | D4: Factor | E4: E (tCO₂e) | F4: Nota
A5: HFC-134a refrigeración comercial [2.F.1] | B5: 985 | C5: kg/año | D5: =SUPUESTOS_FE!$B$11 -> 1430 | E5: =B5*D5/1000 -> 1408.55 | F5: Balance de masa IMBIO 2022; SEMARNAT/SAO
A6: HFC-410A climatización [2.F.2] | B6: 537.81 | C6: kg/año | D6: =SUPUESTOS_FE!$B$12 -> 2088 | E6: =B6*D6/1000 -> 1122.9473 | F6: Balance de masa IMBIO 2022
A7: Industria avícola — proceso [2.H.2] | B7: 8400 | C7: t/año | D7: 0.062 | E7: =B7*D7 -> 520.8 | F7: FE INECC 0.062 kgCO₂e/kg incluye calderas y tratamiento de AR del rastro: reclasificar a 1.A.2 / 4.D (hallazgo M5, pendiente)
A8: Subtotal IPPU contabilizado | E8: =SUM(E5:E7)+E12+E13 -> 3052.2973
A9: de ello HFC | E9: =E5+E6 -> 2531.4973
A10: de ello CO₂ | E10: =E7+E12+E13 -> 520.8
A11: Partidas que solo cuentan si CRITERIOS = SI
A12: Cal en construcción [2.A.2] | B12: =420*(0.7*0.785+0.3*0.593) -> 305.508 | C12: tCO₂ potencial | D12: =CRITERIOS!$B$13 -> NO | E12: =IF(D12="SI",B12,0) -> 0 | F12: 420 t de cal (70 % viva, FE 0.785; 30 % hidratada, FE 0.593). El uso no emite (hallazgo M3)
A13: Textil — COV [2.H.3] | B13: =(41.2+27.2)*4.2 -> 287.28 | C13: tCO₂e potencial | D13: =CRITERIOS!$B$14 -> NO | E13: =IF(D13="SI",B13,0) -> 0 | F13: 68.4 t COV/año (RETC 2022) × 4.2. Los COV no son GEI (hallazgo M4)
A15: Partida informativa (no suma): COV textiles | B15: =41.2+27.2 -> 68.4 | C15: t COV/año | F15: Reportar como contaminante de calidad del aire; la medida I5-B del PAC se reclasifica como cobeneficio

Sheet CONTROL_AUDITORIA
A1: CONTROL DE HALLAZGOS — auditoría del 17-oct-2026 vs memoria v1.4
A3: ID | B3: Nivel | C3: Hallazgo | D3: Estado en v1.4 | E3: Cómo quedó / qué falta
A4: C1 | B4: Crítico | C4: UTCUTS 22,940 no reproducible; sin descontar C de cultivo | D4: Corregido | E4: Promedio anual de 5 años con C cultivo 5 tC/ha (CRITERIOS). Falta verificar con ≥30 parcelas.
A5: C2 | B5: Crítico | C5: CH₄ aguas residuales 3.12: error de unidades y MCF | D5: Corregido | E5: TOW × Bo × MCF por vía. Verificar el MCF 0.03 del Refinamiento 2019 y pedir a INAGUA la DBO del efluente.
A6: C3 | B6: Crítico | C6: N₂O indirecto de suelos 10× menor | D6: Corregido | E6: Fórmulas vivas.
A7: C4 | B7: Crítico | C7: Tabla por gas suma 111 % y cuenta UTCUTS dos veces | D7: Corregido | E7: Distribución por gas derivada de la matriz (RESUMEN fila 11). Corregida la Tabla R2 del Inventario v2.2; falta la web.
A8: C5 | B8: Crítico | C8: Reparto AFOLU CH₄/N₂O no coincide con subcategorías | D8: Corregido | E8: 3_AFOLU §E alimenta la matriz.
A9: C6 | B9: Crítico | C9: Incertidumbre AFOLU ±12–18 % no sostenida | D9: Corregido | E9: Método 1 en 3_AFOLU; resultado en RESUMEN. Texto del Inventario v2.2 y PAC v5 actualizado.
A10: C7 | B10: Crítico | C10: Brecha entre meta −30 % y metas sectoriales | D10: Corregido | E10: Meta en dos niveles: −20 % no condicionada (cubierta por medidas) y −30 % condicionada (RESUMEN).
A11: M1 | B11: Mayor | C11: N₂O aguas residuales sin 44/28 | D11: Corregido | E11: Falta documentar N per cápita y fracción tratada.
A12: M2 | B12: Mayor | C12: FE RSU 3.6 kgCH₄/t sin respaldo IPCC | D12: Corregido | E12: Modelo FOD con 6 fracciones y caracterización municipal 2025 (PEPGIR), desde 2001 (San Nicolás) y 2022 (CARS La Loma).
A13: M3 | B13: Mayor | C13: Cal en construcción no emite CO₂ | D13: Corregido | E13: Fuera del total (CRITERIOS = NO).
A14: M4 | B14: Mayor | C14: COV no son GEI | D14: Corregido | E14: Fuera del total; partida informativa en 5_IPPU.
... A38: N11 | B38: Menor | C38: N de excretas en pastoreo (PRP, 3.C.4) no estimado | D38: Pendiente (nuevo) | E38: Estimar en el siguiente ciclo; aporte menor (5 % del hato bovino).
C40: Corregidos en la memoria | D40: =COUNTIF(D4:D38,"Corregido") -> 32
C41: Pendientes | D41: =COUNTA(D4:D38)-D40 -> 3
